<?xml version="1.0"?>
<robot xmlns:xacro="http://wiki.ros.org/xacro">

  <xacro:macro name="robot_tecnobody" params="parent tf_prefix *origin">

    <!-- Define materials -->
    <material name="white">
      <color rgba="1 1 1 1" />
    </material>

    <material name="grey_transparent">
      <color rgba="0.5 0.5 0.5 0.4" />
    </material>

    <!-- Define world and ee_link -->
    <link name="${tf_prefix}robot_center_plate" />
    <link name="ee_link" />

    <!--Define
    fixed structure links-->
    <link name="col1">
      <visual>
        <geometry>
          <cylinder length="2.5" radius="0.05" />
        </geometry>
        <material name="grey_transparent" />
      </visual>
      <inertial>
        <mass value="50" />
        <inertia ixx="1.0" ixy="0.0" ixz="0.0" iyy="1.0" iyz="0.0" izz="1.0" />
      </inertial>
    </link>

    <link name="col2">
      <visual>
        <geometry>
          <cylinder length="2.5" radius="0.05" />
        </geometry>
        <material name="grey_transparent" />
      </visual>
      <inertial>
        <mass value="50" />
        <inertia ixx="1.0" ixy="0.0" ixz="0.0" iyy="1.0" iyz="0.0" izz="1.0" />
      </inertial>
    </link>

    <link name="col3">
      <visual>
        <geometry>
          <cylinder length="2.5" radius="0.05" />
        </geometry>
        <material name="grey_transparent" />
      </visual>
      <inertial>
        <mass value="50" />
        <inertia ixx="1.0" ixy="0.0" ixz="0.0" iyy="1.0" iyz="0.0" izz="1.0" />
      </inertial>
    </link>

    <link name="beam0">
      <visual>
        <geometry>
          <cylinder length="4" radius="0.05" />
        </geometry>
        <material name="grey_transparent" />
      </visual>
      <inertial>
        <mass value="30" />
        <inertia ixx="1.0" ixy="0.0" ixz="0.0" iyy="1.0" iyz="0.0" izz="1.0" />
      </inertial>
    </link>

    <link name="beam1">
      <visual>
        <geometry>
          <cylinder length="4" radius="0.05" />
        </geometry>
        <material name="grey_transparent" />
      </visual>
      <inertial>
        <mass value="30" />
        <inertia ixx="1.0" ixy="0.0" ixz="0.0" iyy="1.0" iyz="0.0" izz="1.0" />
      </inertial>
    </link>

    <link name="beam2">
      <visual>
        <geometry>
          <cylinder length="4" radius="0.05" />
        </geometry>
        <material name="grey_transparent" />
      </visual>
      <inertial>
        <mass value="30" />
        <inertia ixx="1.0" ixy="0.0" ixz="0.0" iyy="1.0" iyz="0.0" izz="1.0" />
      </inertial>
    </link>

    <link name="beam3">
      <visual>
        <geometry>
          <cylinder length="4" radius="0.05" />
        </geometry>
        <material name="grey_transparent" />
      </visual>
      <inertial>
        <mass value="30" />
        <inertia ixx="1.0" ixy="0.0" ixz="0.0" iyy="1.0" iyz="0.0" izz="1.0" />
      </inertial>
    </link>

    <!-- Define base_link -->
    <link name="base_link">
      <visual>
        <geometry>
          <cylinder length="2.5" radius="0.05" />
        </geometry>
        <material name="white" />
      </visual>
      <inertial>
        <mass value="50" />
        <inertia ixx="1.0" ixy="0.0" ixz="0.0" iyy="1.0" iyz="0.0" izz="1.0" />
      </inertial>
    </link>

    <!-- Define link1 -->
    <link name="link1">
      <visual>
        <geometry>
          <cylinder length="4" radius="0.05" />
        </geometry>
        <material name="white" />
      </visual>
      <inertial>
        <mass value="30" />
        <inertia ixx="1.0" ixy="0.0" ixz="0.0" iyy="1.0" iyz="0.0" izz="1.0" />
      </inertial>
    </link>

    <!-- Define link2 -->
    <link name="link2">
      <visual>
        <geometry>
          <box size="0.1 0.1 0.1" />
        </geometry>
        <material name="white" />
      </visual>
      <inertial>
        <mass value="10" />
        <inertia ixx="1.0" ixy="0.0" ixz="0.0" iyy="1.0" iyz="0.0" izz="1.0" />
      </inertial>
    </link>

    <!-- Define link3 -->
    <link name="link3">
      <visual>
        <geometry>
          <cylinder length="2" radius="0.05" />
        </geometry>
        <material name="white" />
      </visual>
      <inertial>
        <mass value="5" />
        <inertia ixx="1.0" ixy="0.0" ixz="0.0" iyy="1.0" iyz="0.0" izz="1.0" />
      </inertial>
    </link>

    <!-- mount the fts to the robot -->
    <joint name="${tf_prefix}robot_center_joint" type="fixed">
      <xacro:insert_block name="origin" />
      <parent link="${tf_prefix}${parent}" />
      <child link="${tf_prefix}robot_center_plate" />
    </joint>

    <!-- Define active joints -->
    <joint name="base2world" type="fixed">
      <parent link="${tf_prefix}robot_center_plate" />
      <child link="base_link" />
      <origin xyz="0 0 0" rpy="3.14 0 1.57" />
    </joint>

    <!--Define fixed structure joints-->
    <joint name="col1_joint" type="fixed">
      <parent link="base_link" />
      <child link="col1" />
      <origin xyz="4 0 0" rpy="0 0 0" />
    </joint>

    <joint name="col2_joint" type="fixed">
      <parent link="base_link" />
      <child link="col2" />
      <origin xyz="4 -4 0" rpy="0 0 3.14" />
    </joint>

    <joint name="col3_joint" type="fixed">
      <parent link="base_link" />
      <child link="col3" />
      <origin xyz="0 -4 0" rpy="0 0 0" />
    </joint>

    <joint name="beam0_joint" type="fixed">
      <parent link="base_link" />
      <child link="beam0" />
      <origin xyz="0 -2 1.25" rpy="1.57 0 0" />
    </joint>

    <joint name="beam1_joint" type="fixed">
      <parent link="col1" />
      <child link="beam1" />
      <origin xyz="-2 0 1.25" rpy="0 1.57 0" />
    </joint>

    <joint name="beam2_joint" type="fixed">
      <parent link="col2" />
      <child link="beam2" />
      <origin xyz="0 -2 1.25" rpy="1.57 0 0" />
    </joint>

    <joint name="beam3_joint" type="fixed">
      <parent link="col3" />
      <child link="beam3" />
      <origin xyz="2 0 1.25" rpy="0 1.57 0" />
    </joint>

    <joint name="joint_1" type="prismatic">
      <parent link="base_link" />
      <child link="link1" />
      <origin xyz="0.1 -2 1.25" rpy="1.57 0 0" />
      <axis xyz="1 0 0" />
      <limit lower="0" upper="3.8" effort="100" velocity="1" />
    </joint>

    <joint name="joint_2" type="prismatic">
      <parent link="link1" />
      <child link="link2" />
      <origin xyz="0 0 0" rpy="0 0 0" />
      <axis xyz="0 0 1" />
      <limit lower="-1.9" upper="1.9" effort="100" velocity="1" />
    </joint>

    <joint name="joint_3" type="prismatic">
      <parent link="link2" />
      <child link="link3" />
      <origin xyz="0 0 0" rpy="-1.57 0 0" />
      <axis xyz="0 0 1" />
      <limit lower="-1" upper="1" effort="100" velocity="1" />
    </joint>

    <joint name="ee_joint" type="fixed">
      <parent link="link3" />
      <child link="ee_link" />
      <origin xyz="0 0 -1" rpy="0 3.14 0" />
    </joint>
    
  </xacro:macro>
</robot>