<?xml version = "1.0"?>
<robot name = "tecnobody" xmlns:xacro="http://www.ros.org/wiki/xacro">

  <!-- Used for fixing robot to 'base_link' -->
  <link name="world"/>

  <!-- Base Link -->
  <link name = "base_link"/>
  <link name = "link1"/>
  <link name = "link2"/>
  <link name = "link3"/>

  <joint name="base2world" type="fixed">
    <parent link="world"/>
    <child link="base_link"/>
  </joint>

  <joint name = "joint_1" type="revolute">
    <parent link = "base_link"/>
    <child link = "link1"/>
    <origin xyz = "0.05 0.05 0.05"/>
    <limit effort="1000.0" lower="-6.28" upper="6.28" velocity="1000000"/>
    <axis xyz = "0 0 1"/>
    <dynamics damping="0.2" friction="0.1" />
  </joint>

  <joint name = "joint_2" type="revolute">
    <parent link = "base_link"/>
    <child link = "link2"/>
    <origin xyz = "0.15 0.15 0.15"/>
    <limit effort="1000.0" lower="-6.28" upper="6.28" velocity="1000000"/>
    <axis xyz = "0 0 1"/>
    <dynamics damping="0.2" friction="0.1" />
  </joint>

  <joint name = "joint_3" type="revolute">
    <parent link = "base_link"/>
    <child link = "link3"/>
    <origin xyz = "0.1 0.1 0.1"/>
    <limit effort="1000.0" lower="-6.28" upper="6.28" velocity="1000000"/>
    <axis xyz = "0 0 1"/>
    <dynamics damping="0.2" friction="0.1" />
  </joint>

</robot>